Workbook
Name coeff_d_02913344_4cc8_4f3c_b5cd_7d7e9a7f0abe: #REF!
Name coeff_d_345d0e54_e172_4e98_9782_d533d7cc86fc: #REF!
Name OTRO1: #REF!
Name OTRO3: #REF!

Sheet PDM
A1: EJE | B1: PONDERADOR EJE | C1: NOMBRE DE SECTOR | D1: SECTOR MGA | E1: PROGRAMA MGA | F1: COD,.INT. PROGRAMA | G1: PROGRAMA PDT | H1: COD SUBPROGRAMA | I1: COD. INT, SUBPROGRAMA | J1: SUBPROGRAMA | K1: COD. INT. MR | L1: META DE RESULTADO | M1: INDICADOR DE RESULTADO | N1: L.B | O1: PRODUCTO MGA | P1: BPIN | Q1: NOMBRE DEL PROYECTO | R1: COD META PRODUCTO | S1: META DE PRODUCTO | T1: L.B | U1: UNIDAD DE MEDIDA | V1: TENDENCIA INDICADOR | W1: INDICADOR | X1: RESPONSABLE | Y1: PACTO POR LA NIŃEZ | Z1: VALOR ESPERADO CUATRIENIO | AA1: % TOTAL EJEJCUTADO 2024 VS CUATRIENIO | AB1: % TOTAL EJECUTADO 2025 VS CUATRIENIO | AC1: % TOTAL EJECUTADO 2026 VS CUATRIENIO | AD1: % TOTAL EJECUTADO 2027 VS CUATRIENIO | AE1: PORCENTAJE TOTAL PDM AVANCE CUATRIENIO | AF1: VALOR ESPERADO 2024 | AG1: VALOR ESPERADO 2025 | AH1: VALOR ESPERADO 2026 | AI1: VALOR ESPERADO 2027 | AJ1: T1. PLANEADO 2024 | AK1: T1. EJECUTADO 2024 | AL1: T2. PLANEADO 2024 | AM1: T2. EJECUTADO 2024 | AN1: T3. PLANEADO 2024 | AO1: T3. EJECUTADO 2024 | AP1: T4. PLANEADO 2024 | AQ1: T.4 EJECUTADO 2024 | AR1: TOTAL PLANEADO 2024 | AS1: TOTAL EJECUTADO 2024 | AT1: AVANCE 2024 | AU1: % TOTAL PLANEADO 2024 | AV1: % TOTAL AVANCE 2024 | AW1: ESTADO PROGRAMADO-NO PROGRAMADO | AX1: SOPORTES DE CUMPLIMIENTO 2024 | AY1: T1. PLANEADO 2025 | AZ1: T1. EJECUTADO 2025 | BA1: T2. PLANEADO 2025 | BB1: T2. EJECUTADO 2025 | BC1: T3. PLANEADO 2025 | BD1: T3. EJECUTADO 2025 | BE1: T4. PLANEADO 2025 | BF1: T.4 EJECUTADO 2025 | BG1: TOTAL PLANEADO 2025 | BH1: TOTAL EJECUTADO 2025 | BI1: AVANCE 2025 | BJ1: % TOTAL PLANEADO 2025 | BK1: % TOTAL AVANCE 2025 | BL1: ESTADO PROGRAMADO-NO PROGRAMADO | BM1: SOPORTES DE CUMPLIMIENTO 2025 | BN1: APROPIACION DEFINITIVA 2025 | BO1: COMPROMISOS 2025 | BP1: APROPIACION 2024 | BQ1: COMPROMISOS 2024 | BR1: TOTAL ASIGNADO | BS1: TOTAL COMPROMISOS | BT1: % EJECUCIÓN FINANCIERA | BU1: APROPIACION INICIAL 2025 | BV1: APROPIACION DEFINITIVA 2025 | BW1: COMPROMISOS 2025 | BX1: PAGOS 2025 | BY1: % EJECUCION 2025 | BZ1: 2024 PLAN FINANCIERO PDM | CA1: 2025 PLAN FINANCIERO PDM | CB1: 2026 PLAN FINANCIERO PDM | CC1: 2027 PLAN FINANCIERO PDM | CD1: TOTALES PLAN FINANCIERO PDM
A2: Eje 1. Ambiente, Conectividad y Ordenamiento y servicios públicos | B2: 0.235 | D2: 32 | E2: 3204 | F2: 1 | G2: Programa Integral de Sostenibilidad y Educación Ambiental (PISEA) (Gestión Intergal del recurso hídrico) | H2: 0900 | I2: 1.1 | J2: CUSOR- Conservación y Uso Sostenible de los Recursos Hídricos | K2: 1.1.1 | L2: Implementar al 100% las acciones integrales para la protección de áreas de interés hídrico, caracterización y conservación del recurso hídrico y la ejecución de políticas efectivas para la gestión del cambio climático | M2: Porcentaje de acciones integrales para la protección de áreas de interés hídrico, caracterización y conservación del recurso hídrico implementadas | N2: 0 | O2: 3204001 | P2: 2024257990001 | Q2: Implementación de la educacion, sensibilizacion ambiental y Uso Sostenible de los Recursos Hídricos en el Municipio de Tenjo Cundinamarca | R2: 1 | S2: Dar cumplimiento a las estrategias enmarcadas en el art. 111 de la Ley 99 de 1993 "Adquisición o mantenimiento de áreas de interés para acueductos municipales, distritales y regionales" | T2: 2 Estrategias (Reforestación y manteniniento) 880 has DMI 308 Has de propiedad del municipio | U2: Número | V2: I | W2: Actividades desarrolladas | X2: Secretaría de Desarrollo Económico y Medio Ambiente o quien haga sus veces | Z2: =SUM(AF2:AI2) -> 4 | AA2: =AS2/Z2 -> 0.25 | AB2: =BI2/Z2 -> 0.2125 | AE2: =SUMPRODUCT(AA2:AD2, {0.15,0.35,0.35,0.15}) -> 0.111875 | AF2: 1 | AG2: 1 | AH2: 1 | AI2: 1 | AN2: 0.7 | AO2: 0.7 | AP2: 0.3 | AQ2: 0.3 | AR2: =(AJ2+AL2+AN2+AP2) -> 1 | AS2: =(AK2+AM2+AO2+AQ2) -> 1 | AT2: =AS2/AR2 -> 1 | AU2: =MIN((AR2 /AR2) * 100, 100) & "%" -> 100% | AV2: =IF(AR2=0, 0, AS2/AR2) -> 1 | AW2: P | AX2: META 1 | AY2: 0.15 | AZ2: 0.15 | BA2: 0.35 | BB2: 0.35 | BC2: 0.35 | BD2: 0.35 | BE2: 0.15 | BG2: =(AY2+BA2+BC2+BE2) -> 1 | BH2: =(AZ2+BB2+BD2+BF2) -> 0.85 | BI2: =BH2/BG2 -> 0.85 | BJ2: =MIN((BG2 /BG2) * 100, 100) & "%" -> 100% | BK2: =IF(BG2=0, 0, BH2/BG2) -> 0.85 | BL2: P | BM2: Meta 1.docx | BN2: 3404125267 | BO2: 205200000 | BP2: 52700000 | BQ2: 52700000 | BR2: =+BN2+BP2 -> 3456825267 | BS2: =+BO2+BQ2 -> 257900000 | BT2: =IFERROR(BS2/BR2, "") -> 0.074606027 | BU2: 924152848 | BV2: 3404125267 | BW2: 1405200000 | BX2: 148860000 | BY2: =IFERROR(BW2/BV2, "") -> 0.41279327 | BZ2: 913789867 | CA2: 950341565 | CB2: 993344662 | CC2: 1035710435 | CD2: 3893186529
A3: Eje 1. Ambiente, Conectividad y Ordenamiento y servicios públicos | B3: 0.235 | D3: 32 | E3: 3204 | F3: 1 | G3: Programa Integral de Sostenibilidad y Educación Ambiental (PISEA) (Gestión Intergal del recurso hídrico) | H3: 0900 | I3: 1.1 | J3: CUSOR- Conservación y Uso Sostenible de los Recursos Hídricos | K3: 1.1.1 | L3: Implementar al 100% las acciones integrales para la protección de áreas de interés hídrico, caracterización y conservación del recurso hídrico y la ejecución de políticas efectivas para la gestión del cambio climático | M3: Porcentaje de acciones integrales para la protección de áreas de interés hídrico, caracterización y conservación del recurso hídrico implementadas | N3: 0 | O3: 3204002 | P3: 2024257990001 | Q3: Implementación de la educacion, sensibilizacion ambiental y Uso Sostenible de los Recursos Hídricos en el Municipio de Tenjo Cundinamarca | R3: 2 | S3: Implementar 1 estrategia para la caracterización y conservación del recurso hídrico del municipio en el marco del POMCA del Río Bogotá y de la Sentencia del Río Bogotá | T3: 0 | U3: Número | V3: I | W3: Número de actividades realizadas | X3: Secretaría de Desarrollo Económico y Medio Ambiente o quien haga sus veces | Z3: =SUM(AF3:AI3) -> 4 | AA3: =AS3/Z3 -> 0.2475 | AB3: =BI3/Z3 -> 0.2125 | AE3: =SUMPRODUCT(AA3:AD3, {0.15,0.35,0.35,0.15}) -> 0.1115 | AF3: 1 | AG3: 1 | AH3: 1 | AI3: 1 | AN3: 0.65 | AO3: 0.65 | AP3: 0.35 | AQ3: 0.34 | AR3: =(AJ3+AL3+AN3+AP3) -> 1 | AS3: =(AK3+AM3+AO3+AQ3) -> 0.99 | AT3: =AS3/AR3 -> 0.99 | AU3: =MIN((AR3 /AR3) * 100, 100) & "%" -> 100% | AV3: =IF(AR3=0, 0, AS3/AR3) -> 0.99 | AW3: P | AX3: META 2 | AY3: 0.15 | AZ3: 0.15 | BA3: 0.35 | BB3: 0.35 | BC3: 0.35 | BD3: 0.35 | BE3: 0.15 | BG3: =(AY3+BA3+BC3+BE3) -> 1 | BH3: =(AZ3+BB3+BD3+BF3) -> 0.85 | BI3: =BH3/BG3 -> 0.85 | BJ3: =MIN((BG3 /BG3) * 100, 100) & "%" -> 100% | BK3: =IF(BG3=0, 0, BH3/BG3) -> 0.85 | BL3: P | BM3: Meta 2.docx | BN3: 419330408 | BO3: 151546432 | BP3: 91418093 | BQ3: 91418093 | BR3: =+BN3+BP3 -> 510748501 | BS3: =+BO3+BQ3 -> 242964525 | BT3: =IFERROR(BS3/BR3, "") -> 0.47570286 | BU3: 315064557 | BV3: 419330408 | BW3: 198752519 | BX3: 147625458 | BY3: =IFERROR(BW3/BV3, "") -> 0.47397593 | BZ3: 210000000 | CA3: 214200000 | CB3: 218484000 | CC3: 225038520 | CD3: 867722520
A4: Eje 1. Ambiente, Conectividad y Ordenamiento y servicios públicos | B4: 0.235 | D4: 32 | E4: 3204 | F4: 1 | G4: Programa Integral de Sostenibilidad y Educación Ambiental (PISEA) (Gestión Intergal del recurso hídrico) | H4: 0900 | I4: 1.1 | J4: CUSOR- Conservación y Uso Sostenible de los Recursos Hídricos | K4: 1.1.1 | L4: Implementar al 100% las acciones integrales para la protección de áreas de interés hídrico, caracterización y conservación del recurso hídrico y la ejecución de políticas efectivas para la gestión del cambio climático | M4: Porcentaje de acciones integrales para la protección de áreas de interés hídrico, caracterización y conservación del recurso hídrico implementadas | N4: 0 | O4: 3204006 | P4: 2024257990001 | Q4: Implementación de la educacion, sensibilizacion ambiental y Uso Sostenible de los Recursos Hídricos en el Municipio de Tenjo Cundinamarca | R4: 3 | S4: Implementar 4 líneas estratégicas de la política pública de gestión integral del cambio climático departamental (ORDENANZA No. 0112/2023) | T4: 0 | U4: Número | V4: I | W4: 4 líneas estratégicas implementadas | X4: Secretaría de Desarrollo Económico y Medio Ambiente o quien haga sus veces | Z4: =SUM(AF4:AI4) -> 4 | AA4: =AS4/Z4 -> 0.25 | AB4: =BI4/Z4 -> 0.11842105 | AE4: =SUMPRODUCT(AA4:AD4, {0.15,0.35,0.35,0.15}) -> 0.078947368 | AF4: 1 | AG4: 1 | AH4: 1 | AI4: 1 | AN4: 0.2 | AO4: 0.2 | AP4: 0.8 | AQ4: 0.8 | AR4: =(AJ4+AL4+AN4+AP4) -> 1 | AS4: =(AK4+AM4+AO4+AQ4) -> 1 | AT4: =AS4/AR4 -> 1 | AU4: =MIN((AR4 /AR4) * 100, 100) & "%" -> 100% | AV4: =IF(AR4=0, 0, AS4/AR4) -> 1 | AW4: P | AX4: META 3 | AY4: 0.15 | AZ4: 0 | BA4: 0.1 | BB4: 0.1 | BC4: 0.35 | BD4: 0.35 | BE4: 0.35 | BG4: =(AY4+BA4+BC4+BE4) -> 0.95 | BH4: =(AZ4+BB4+BD4+BF4) -> 0.45 | BI4: =BH4/BG4 -> 0.47368421 | BJ4: =MIN((BG4 /BG4) * 100, 100) & "%" -> 100% | BK4: =IF(BG4=0, 0, BH4/BG4) -> 0.47368421 | BL4: P | BM4: Meta 3.docx | BN4: 234094874 | BO4: 0 | BP4: 183385555 | BQ4: 183385555 | BR4: =+BN4+BP4 -> 417480429 | BS4: =+BO4+BQ4 -> 183385555 | BT4: =IFERROR(BS4/BR4, "") -> 0.43926743 | BU4: 130000000 | BV4: 234094874 | BW4: 0 | BX4: 0 | BY4: =IFERROR(BW4/BV4, "") -> 0 | BZ4: 159000000 | CA4: 162180000 | CB4: 165423600 | CC4: 170386308 | CD4: 656989908
A5: Eje 1. Ambiente, Conectividad y Ordenamiento y servicios públicos | B5: 0.235 | D5: 32 | E5: 3204 | F5: 1 | G5: Programa Integral de Sostenibilidad y Educación Ambiental (PISEA) (Gestión Intergal del recurso hídrico) | H5: 0900 | I5: 1.2 | J5: Es el Tiempo de la Educación y Sensibilización Ambiental | K5: 1.1.2 | L5: Implementar en 25% la Política Pública de Educación Ambiental, actualizando y ejecutando completamente el Plan Institucional de Gestión Ambiental (PIGA), y fomentando la participación de la comunidad en la preservación y valoración de los recursos naturales a través de programas educativos | M5: Porcentaje de política de Educación Ambiental implementado | N5: 0 | O5: 3204001 | P5: 2024257990001 | Q5: Implementación de la educacion, sensibilizacion ambiental y Uso Sostenible de los Recursos Hídricos en el Municipio de Tenjo Cundinamarca | R5: 4 | S5: Formular e implementar al 25% la Política Pública de Educación Ambiental | T5: 0 | U5: Porcentaje | V5: I | W5: 1 política Pública formulada e implementada al 25% | X5: Secretaría de Desarrollo Económico y Medio Ambiente o quien haga sus veces | Z5: =SUM(AF5:AI5) -> 0.25 | AA5: =AS5/Z5 -> 0.2 | AB5: =BI5/Z5 -> 3.2 | AE5: =SUMPRODUCT(AA5:AD5, {0.15,0.35,0.35,0.15}) -> 1.15 | AF5: 0.04 | AG5: 0.08 | AH5: 0.1 | AI5: 0.03 | AN5: 0.04 | AO5: 0.04 | AP5: 0.04 | AQ5: 0.01 | AR5: =(AJ5+AL5+AN5+AP5) -> 0.08 | AS5: =(AK5+AM5+AO5+AQ5) -> 0.05 | AT5: =AS5/AR5 -> 0.625 | AU5: =MIN((AR5 /AR5) * 100, 100) & "%" -> 100% | AV5: =IF(AR5=0, 0, AS5/AR5) -> 0.625 | AW5: P | AX5: META 4 | AY5: 0.05 | AZ5: 0.05 | BA5: 0.1 | BB5: 0.1 | BC5: 0.05 | BD5: 0.05 | BE5: 0.05 | BG5: =(AY5+BA5+BC5+BE5) -> 0.25 | BH5: =(AZ5+BB5+BD5+BF5) -> 0.2 | BI5: =BH5/BG5 -> 0.8 | BJ5: =MIN((BG5 /BG5) * 100, 100) & "%" -> 100% | BK5: =IF(BG5=0, 0, BH5/BG5) -> 0.8 | BL5: P | BM5: Meta 4.docx | BN5: 100000000 | BO5: 0 | BP5: 0 | BQ5: 0 | BR5: =+BN5+BP5 -> 100000000 | BS5: =+BO5+BQ5 -> 0 | BT5: =IFERROR(BS5/BR5, "") -> 0 | BU5: 60000000 | BV5: 100000000 | BW5: 60000000 | BX5: 26333332 | BY5: =IFERROR(BW5/BV5, "") -> 0.6 | BZ5: 45000000 | CA5: 45900000 | CB5: 46818000 | CC5: 48222540 | CD5: 185940540
A6: Eje 1. Ambiente, Conectividad y Ordenamiento y servicios públicos | B6: 0.235 | D6: 32 | E6: 3204 | F6: 1 | G6: Programa Integral de Sostenibilidad y Educación Ambiental (PISEA) (Gestión Intergal del recurso hídrico) | H6: 0900 | I6: 1.2 | J6: Es el Tiempo de la Educación y Sensibilización Ambiental | K6: 1.1.2 | L6: Implementar en 25% la Política Pública de Educación Ambiental, actualizando y ejecutando completamente el Plan Institucional de Gestión Ambiental (PIGA), y fomentando la participación de la comunidad en la preservación y valoración de los recursos naturales a través de programas educativos | M6: Porcentaje de política de Educación Ambiental implementado | N6: 0 | O6: 3204001 | P6: 2024257990001 | Q6: Implementación de la educacion, sensibilizacion ambiental y Uso Sostenible de los Recursos Hídricos en el Municipio de Tenjo Cundinamarca | R6: 5 | S6: Actualizar e implementar el Plan Institucional de Gestión Ambiental PIGA | T6: 1 | U6: Número | V6: M | W6: 1 plan actualizado e implementado | X6: Secretaría de Desarrollo Económico y Medio Ambiente o quien haga sus veces | Z6: =SUM(AF6:AI6) -> 1 | AA6: =AS6/Z6 -> 1 | AB6: =BI6/Z6 -> 1 | AE6: =SUMPRODUCT(AA6:AD6, {0.15,0.35,0.35,0.15}) -> 0.5 | AF6: 0.1 | AG6: 0.4 | AH6: 0.4 | AI6: 0.1 | AN6: 0.7 | AO6: 0.7 | AP6: 0.3 | AQ6: 0.3 | AR6: =(AJ6+AL6+AN6+AP6) -> 1 | AS6: =(AK6+AM6+AO6+AQ6) -> 1 | AT6: =AS6/AR6 -> 1 | AU6: =MIN((AR6 /AR6) * 100, 100) & "%" -> 100% | AV6: =IF(AR6=0, 0, AS6/AR6) -> 1 | AW6: P | AX6: META 5 | AY6: 0.1 | AZ6: 0.1 | BA6: 0.1 | BB6: 0.1 | BC6: 0.2 | BD6: 0.2 | BE6: 0 | BG6: =(AY6+BA6+BC6+BE6) -> 0.4 | BH6: =(AZ6+BB6+BD6+BF6) -> 0.4 | BI6: =BH6/BG6 -> 1 | BJ6: =MIN((BG6 /BG6) * 100, 100) & "%" -> 100% | BK6: =IF(BG6=0, 0, BH6/BG6) -> 1 | BL6: P | BM6: Meta 5.docx | BN6: 39048521 | BO6: 34240000 | BP6: 11778450 | BQ6: 11778450 | BR6: =+BN6+BP6 -> 50826971 | BS6: =+BO6+BQ6 -> 46018450 | BT6: =IFERROR(BS6/BR6, "") -> 0.9053943 | BU6: 35826971 | BV6: 39048521 | BW6: 34240000 | BX6: 24853333 | BY6: =IFERROR(BW6/BV6, "") -> 0.87685779 | BZ6: 60000000 | CA6: 61200000 | CB6: 62424000 | CC6: 64296720 | CD6: 247920720
A7: Eje 1. Ambiente, Conectividad y Ordenamiento y servicios públicos | B7: 0.235 | D7: 32 | E7: 3204 | F7: 1 | G7: Programa Integral de Sostenibilidad y Educación Ambiental (PISEA) (Gestión Intergal del recurso hídrico) | H7: 0900 | I7: 1.2 | J7: Es el Tiempo de la Educación y Sensibilización Ambiental | K7: 1.1.2 | L7: Implementar en 25% la Política Pública de Educación Ambiental, actualizando y ejecutando completamente el Plan Institucional de Gestión Ambiental (PIGA), y fomentando la participación de la comunidad en la preservación y valoración de los recursos naturales a través de programas educativos | M7: Porcentaje de política de Educación Ambiental implementado | N7: 0 | O7: 3204049 | P7: 2024257990001 | Q7: Implementación de la educacion, sensibilizacion ambiental y Uso Sostenible de los Recursos Hídricos en el Municipio de Tenjo Cundinamarca | R7: 6 | S7: Ejecutar un modelo de sensibilización de potencialidades ambientales involucrando la comunidad educativa, grupos ambientalistas, JAC y comunidad en general | T7: 0 | U7: Número | V7: I | W7: Modelo ejecutado | X7: Secretaría de Desarrollo Económico y Medio Ambiente o quien haga sus veces | Z7: =SUM(AF7:AI7) -> 1 | AA7: =AS7/Z7 -> 1 | AB7: =BI7/Z7 -> 0.425 | AE7: =SUMPRODUCT(AA7:AD7, {0.15,0.35,0.35,0.15}) -> 0.29875 | AF7: 0.1 | AG7: 0.4 | AH7: 0.4 | AI7: 0.1 | AN7: 0.5 | AO7: 0.5 | AP7: 0.5 | AQ7: 0.5 | AR7: =(AJ7+AL7+AN7+AP7) -> 1 | AS7: =(AK7+AM7+AO7+AQ7) -> 1 | AT7: =AS7/AR7 -> 1 | AU7: =MIN((AR7 /AR7) * 100, 100) & "%" -> 100% | AV7: =IF(AR7=0, 0, AS7/AR7) -> 1 | AW7: P | AX7: META 6 | AY7: 0.1 | AZ7: 0.1 | BA7: 0.1 | BB7: 0.05 | BC7: 0.1 | BD7: 0.02 | BE7: 0.1 | BG7: =(AY7+BA7+BC7+BE7) -> 0.4 | BH7: =(AZ7+BB7+BD7+BF7) -> 0.17 | BI7: =BH7/BG7 -> 0.425 | BJ7: =MIN((BG7 /BG7) * 100, 100) & "%" -> 100% | BK7: =IF(BG7=0, 0, BH7/BG7) -> 0.425 | BL7: P | BM7: Meta 6.docx | BN7: 55308000 | BO7: 38633333 | BP7: 209500000 | BQ7: 209500000 | BR7: =+BN7+BP7 -> 264808000 | BS7: =+BO7+BQ7 -> 248133333 | BT7: =IFERROR(BS7/BR7, "") -> 0.93703111 | BU7: 55308000 | BV7: 49633333 | BW7: 38633333 | BX7: 8233333 | BY7: =IFERROR(BW7/BV7, "") -> 0.77837475 | BZ7: 67000000 | CA7: 68340000 | CB7: 69706800 | CC7: 71798004 | CD7: 276844804
A8: Eje 1. Ambiente, Conectividad y Ordenamiento y servicios públicos | B8: 0.235 | D8: 32 | E8: 3204 | F8: 1 | G8: Programa Integral de Sostenibilidad y Educación Ambiental (PISEA) (Gestión Intergal del recurso hídrico) | H8: 0900 | I8: 1.2 | J8: Es el Tiempo de la Educación y Sensibilización Ambiental | K8: 1.1.2 | L8: Implementar en 25% la Política Pública de Educación Ambiental, actualizando y ejecutando completamente el Plan Institucional de Gestión Ambiental (PIGA), y fomentando la participación de la comunidad en la preservación y valoración de los recursos naturales a través de programas educativos | M8: Porcentaje de política de Educación Ambiental implementado | N8: 0 | O8: 3204056 | P8: 2024257990001 | Q8: Implementación de la educacion, sensibilizacion ambiental y Uso Sostenible de los Recursos Hídricos en el Municipio de Tenjo Cundinamarca | R8: 7 | S8: Ejecutar al 100% los PROCEDAS | T8: 1 | U8: Porcentaje | V8: M | W8: Porcentaje PROCEDAS ejecutado | X8: Secretaría de Desarrollo Económico y Medio Ambiente o quien haga sus veces | Y8: SI | Z8: =SUM(AF8:AI8)/4 -> 1 | AA8: =AS8/Z8 -> 0.4375 | AB8: =BI8/Z8 -> 0.75 | AE8: =SUMPRODUCT(AA8:AD8, {0.15,0.35,0.35,0.15}) -> 0.328125 | AF8: 1 | AG8: 1 | AH8: 1 | AI8: 1 | AN8: 0.75 | AO8: 0.75 | AP8: 0.25 | AQ8: 0.125 | AR8: =(AJ8+AL8+AN8+AP8)/2 -> 0.5 | AS8: =(AK8+AM8+AO8+AQ8)/2 -> 0.4375 | AT8: =AS8/AR8 -> 0.875 | AU8: =MIN((AR8 /AR8) * 100, 100) & "%" -> 100% | AV8: =IF(AR8=0, 0, AS8/AR8) -> 0.875 | AW8: P | AX8: META 7 | AY8: 0.15 | AZ8: 0.15 | BA8: 0.3 | BB8: 0.3 | BC8: 0.3 | BD8: 0.3 | BE8: 0.25 | BG8: =(AY8+BA8+BC8+BE8) -> 1 | BH8: =(AZ8+BB8+BD8+BF8) -> 0.75 | BI8: =BH8/BG8 -> 0.75 | BJ8: =MIN((BG8 /BG8) * 100, 100) & "%" -> 100% | BK8: =IF(BG8=0, 0, BH8/BG8) -> 0.75 | BL8: P | BM8: Meta 7.docx | BN8: 81500000 | BO8: 30000000 | BP8: 10000000 | BQ8: 10000000 | BR8: =+BN8+BP8 -> 91500000 | BS8: =+BO8+BQ8 -> 40000000 | BT8: =IFERROR(BS8/BR8, "") -> 0.43715847 | BU8: 60000000 | BV8: 81500000 | BW8: 30000000 | BX8: 21200000 | BY8: =IFERROR(BW8/BV8, "") -> 0.36809816 | BZ8: 30000000 | CA8: 30600000 | CB8: 31212000 | CC8: 32148360 | CD8: 123960360
A9: Eje 1. Ambiente, Conectividad y Ordenamiento y servicios públicos | B9: 0.235 | D9: 40 | E9: 4002 | F9: 2 | G9: Programa Integral de Transformación Urbana (PINTU) (Ordenamiento territorial y desarrollo urbano) | H9: 1400 | I9: 2.1 | J9: Es el tiempo de la legalización y saneamiento urbanístico | K9: 2.1.1 | L9: Asegurar al 100% la eficacia en la gestión y regulación de propiedades para el uso público en el municipio, logrando la legalización y saneamiento para infraestructura y equipamiento público | M9: Porcentaje de eficacia en la gestión y regulación de propiedades para el uso público en el municipio asegurado | N9: 0 | O9: 4002016 | P9: 2024257990002 | Q9: Fortalecimiento integral del programa de transformacion Urbana en el Municipio de Tenjo Cundinamarca | R9: 8 | S9: Realizar en mínimo 10 predios de interés el proceso de formalización y saneamiento | T9: 0 | U9: Número | V9: I | W9: Número de predios de interés con proceso de formalización y saneamiento | X9: Sec. de Planeación y Desarrollo Territorial | Z9: =SUM(AF9:AI9) -> 10 | AA9: =AS9/Z9 -> 0.2 | AB9: =BI9/Z9 -> 0.1 | AE9: =SUMPRODUCT(AA9:AD9, {0.15,0.35,0.35,0.15}) -> 0.065 | AF9: 2 | AG9: 6 | AH9: 2 | AI9: 0 | AN9: 1 | AO9: 1 | AP9: 1 | AQ9: 1 | AR9: =(AJ9+AL9+AN9+AP9) -> 2 | AS9: =(AK9+AM9+AO9+AQ9) -> 2 | AT9: =AS9/AR9 -> 1 | AU9: =MIN((AR9 /AR9) * 100, 100) & "%" -> 100% | AV9: =IF(AR9=0, 0, AS9/AR9) -> 1 | AW9: P | AX9: Meta 8.docx | AY9: 2 | AZ9: 2 | BA9: 4 | BB9: 4 | BC9: 0 | BD9: 0 | BE9: 0 | BF9: 0 | BG9: =(AY9+BA9+BC9+BE9) -> 6 | BH9: =(AZ9+BB9+BD9+BF9) -> 6 | BI9: =BH9/BG9 -> 1 | BJ9: =MIN((BG9 /BG9) * 100, 100) & "%" -> 100% | BK9: =IF(BG9=0, 0, BH9/BG9) -> 1 | BL9: P | BM9: Meta 8.docx | BN9: 95000000 | BO9: 60000000 | BP9: 21000000 | BQ9: 21000000 | BR9: =+BN9+BP9 -> 116000000 | BS9: =+BO9+BQ9 -> 81000000 | BT9: =IFERROR(BS9/BR9, "") -> 0.69827586 | BU9: 60000000 | BV9: 70000000 | BW9: 70000000 | BX9: 55800000 | BY9: =IFERROR(BW9/BV9, "") -> 1 | BZ9: 70000000 | CA9: 71400000 | CB9: 72828000 | CC9: 75012840 | CD9: 289240840
A10: Eje 1. Ambiente, Conectividad y Ordenamiento y servicios públicos | B10: 0.235 | D10: 40 | E10: 4002 | F10: 2 | G10: Programa Integral de Transformación Urbana (PINTU) (Ordenamiento territorial y desarrollo urbano) | H10: 1400 | I10: 2.1 | J10: Es el tiempo de la legalización y saneamiento urbanístico | K10: 2.1.1 | L10: Asegurar al 100% la eficacia en la gestión y regulación de propiedades para el uso público en el municipio, logrando la legalización y saneamiento para infraestructura y equipamiento público | M10: Porcentaje de eficacia en la gestión y regulación de propiedades para el uso público en el municipio asegurado | N10: 0 | O10: 4002040 | P10: 2024257990002 | Q10: Fortalecimiento integral del programa de transformacion Urbana en el Municipio de Tenjo Cundinamarca | R10: 9 | S10: Realizar la titulación del 80% de bienes destinados al uso público en actuaciones urbanísticas a favor del municipio | T10: 0.1 | U10: Porcentaje | V10: I | W10: Porcentaje de funcionamiento del Banco Inmobiliario | X10: Sec. de Urbanismo | Z10: =SUM(AF10:AI10) -> 0.8 | AA10: =AS10/Z10 -> 0.4375 | AB10: =BI10/Z10 -> 0.9375 | AE10: =SUMPRODUCT(AA10:AD10, {0.15,0.35,0.35,0.15}) -> 0.39375 | AF10: 0.1 | AG10: 0.2 | AH10: 0.3 | AI10: 0.2 | AN10: 0.07 | AO10: 0.07 | AP10: 0.28 | AQ10: 0.28 | AR10: =(AJ10+AL10+AN10+AP10) -> 0.35 | AS10: =(AK10+AM10+AO10+AQ10) -> 0.35 | AT10: =AS10/AR10 -> 1 | AU10: =MIN((AR10 /AR10) * 100, 100) & "%" -> 100% | AV10: =IF(AR10=0, 0, AS10/AR10) -> 1 | AW10: P | AX10: META 09.docx | AY10: 0.05 | AZ10: 0.05 | BA10: 0.05 | BB10: 0.05 | BC10: 0.05 | BD10: 0.05 | BE10: 0.05 | BG10: =(AY10+BA10+BC10+BE10) -> 0.2 | BH10: =(AZ10+BB10+BD10+BF10) -> 0.15 | BI10: =BH10/BG10 -> 0.75 | BJ10: =MIN((BG10 /BG10) * 100, 100) & "%" -> 100% | BK10: =IF(BG10=0, 0, BH10/BG10) -> 0.75 | BL10: P | BM10: Meta 9.docx | BN10: 60000000 | BO10: 58773333 | BP10: 29500000 | BQ10: 29500000 | BR10: =+BN10+BP10 -> 89500000 | BS10: =+BO10+BQ10 -> 88273333 | BT10: =IFERROR(BS10/BR10, "") -> 0.98629422 | BU10: 60000000 | BV10: 60000000 | BW10: 58773333 | BX10: 42140372 | BY10: =IFERROR(BW10/BV10, "") -> 0.97955555 | BZ10: 90000000 | CA10: 91800000 | CB10: 93636000 | CC10: 96445080 | CD10: 371881080
A11: Eje 1. Ambiente, Conectividad y Ordenamiento y servicios públicos | B11: 0.235 | D11: 40 | E11: 4002 | F11: 2 | G11: Programa Integral de Transformación Urbana (PINTU) (Ordenamiento territorial y desarrollo urbano) | H11: 1400 | I11: 2.1 | J11: Es el tiempo de la legalización y saneamiento urbanístico | K11: 2.1.1 | L11: Asegurar al 100% la eficacia en la gestión y regulación de propiedades para el uso público en el municipio, logrando la legalización y saneamiento para infraestructura y equipamiento público | M11: Porcentaje de eficacia en la gestión y regulación de propiedades para el uso público en el municipio asegurado | N11: 0 | O11: 4002042 | P11: 2024257990002 | Q11: Fortalecimiento integral del programa de transformacion Urbana en el Municipio de Tenjo Cundinamarca | R11: 10 | S11: Ejecutar al 100 % un proceso con la empresa inmobiliaria de Cundinamarca para la compra y adquisición de predios para uso institucional, dotacional, espacio público, cultural y otros. | T11: 1 | U11: Porcentaje | V11: M | W11: Porcentaje del proceso de compra de predios ejecutados | X11: Sec. de Urbanismo | Z11: =SUM(AF11:AI11)/2 -> 1 | AA11: =AS11/Z11 -> 1 | AB11: =BI11/Z11 -> 0.75 | AE11: =SUMPRODUCT(AA11:AD11, {0.15,0.35,0.35,0.15}) -> 0.4125 | AF11: 1 | AG11: 0 | AH11: 1 | AI11: 0 | AN11: 1 | AO11: 1 | AP11: 0 | AQ11: 0 | AR11: =(AJ11+AL11+AN11+AP11) -> 1 | AS11: =(AK11+AM11+AO11+AQ11) -> 1 | AT11: =AS11/AR11 -> 1 | AU11: =MIN((AR11 /AR11) * 100, 100) & "%" -> 100% | AV11: =IF(AR11=0, 0, AS11/AR11) -> 1 | AW11: P | AX11: META 10.docx | AY11: 1 | AZ11: 1 | BA11: 1 | BB11: 1 | BC11: 1 | BD11: 1 | BE11: 1 | BF11: 0 | BG11: =(AY11+BA11+BC11+BE11)/4 -> 1 | BH11: =(AZ11+BB11+BD11+BF11)/4 -> 0.75 | BI11: =BH11/BG11 -> 0.75 | BJ11: =MIN((BG11 /BG11) * 100, 100) & "%" -> 100% | BK11: =IF(BG11=0, 0, BH11/BG11) -> 0.75 | BL11: P | BM11: Meta 10.docx | BN11: 40000000 | BO11: 0 | BP11: 0 | BQ11: 0 | BR11: =+BN11+BP11 -> 40000000 | BS11: =+BO11+BQ11 -> 0 | BT11: =IFERROR(BS11/BR11, "") -> 0 | BU11: 0 | BV11: 40000000 | BW11: 40000000 | BX11: 0 | BY11: =IFERROR(BW11/BV11, "") -> 1 | BZ11: 40000000 | CA11: 40800000 | CB11: 41616000 | CC11: 42864480 | CD11: 165280480
A12: Eje 1. Ambiente, Conectividad y Ordenamiento y servicios públicos | B12: 0.235 | D12: 40 | E12: 4002 | F12: 2 | G12: Programa Integral de Transformación Urbana (PINTU) (Ordenamiento territorial y desarrollo urbano) | H12: 1400 | I12: 2,2 | J12: Acciones urbanísticas innovadoras | K12: 2.2.1 | L12: Optimizar al 100% la gestión y regulación del uso del suelo en el municipio | M12: Porcentaje de gestión y regulación del uso del suelo optimizada | N12: 0 | O12: 4002036 | P12: 2024257990002 | Q12: Fortalecimiento integral del programa de transformacion Urbana en el Municipio de Tenjo Cundinamarca | R12: 11 | S12: Implementar anualmente un programa de gestión urbanística y financiación del suelo | T12: 1 | U12: Número | V12: M | W12: Programa de revisión de instrumentos de gestión y financiación del suelo implementado | X12: Sec. de Urbanismo | Z12: =SUM(AF12:AI12) -> 4 | AA12: =AS12/Z12 -> 0.2375 | AB12: =BI12/Z12 -> 0.2125 | AE12: =SUMPRODUCT(AA12:AD12, {0.15,0.35,0.35,0.15}) -> 0.11 | AF12: 1 | AG12: 1 | AH12: 1 | AI12: 1 | AN12: 0.7 | AO12: 0.7 | AP12: 0.3 | AQ12: 0.25 | AR12: =(AJ12+AL12+AN12+AP12) -> 1 | AS12: =(AK12+AM12+AO12+AQ12) -> 0.95 | AT12: =AS12/AR12 -> 0.95 | AU12: =MIN((AR12 /AR12) * 100, 100) & "%" -> 100% | AV12: =IF(AR12=0, 0, AS12/AR12) -> 0.95 | AW12: P | AX12: META 11.docx | AY12: 0.25 | AZ12: 0.25 | BA12: 0.3 | BB12: 0.3 | BC12: 0.3 | BD12: 0.3 | BE12: 0.15 | BG12: =(AY12+BA12+BC12+BE12) -> 1 | BH12: =(AZ12+BB12+BD12+BF12) -> 0.85 | BI12: =BH12/BG12 -> 0.85 | BJ12: =MIN((BG12 /BG12) * 100, 100) & "%" -> 100% | BK12: =IF(BG12=0, 0, BH12/BG12) -> 0.85 | BL12: P | BM12: Meta 11.docx | BN12: 420000000 | BO12: 280610000 | BP12: 144661334 | BQ12: 144661334 | BR12: =+BN12+BP12 -> 564661334 | BS12: =+BO12+BQ12 -> 425271334 | BT12: =IFERROR(BS12/BR12, "") -> 0.75314407 | BU12: 420000000 | BV12: 327110000 | BW12: 327110000 | BX12: 209617959 | BY12: =IFERROR(BW12/BV12, "") -> 1 | BZ12: 200000000 | CA12: 204000000 | CB12: 208080000 | CC12: 214322400 | CD12: 826402400
A13: Eje 1. Ambiente, Conectividad y Ordenamiento y servicios públicos | B13: 0.235 | D13: 45 | E13: 4599 | F13: 3 | G13: Programa Avanzado de Gestión Territorial Inteligente (PRAGETI) (Fortalecimiento a la gestión y dirección de la gestió pública territorial) | H13: 1000 | I13: 3.1 | J13: Sistemas de Información y datos para la toma de decisiones | K13: 3.1.1 | L13: Implementar al 100% el sistema de Información y datos de gestión del desarrollo territorial y toma de decisiones, mediante la implementación efectiva de tecnologías avanzadas en análisis de datos y la optimización del funcionamiento de los consejos y comités de planificación y estratificación | M13: Porcentaje de sistema de Información y datos implementado | N13: 0.71 | O13: 4599005 | P13: 2024257990003 | Q13: Fortalecimiento a la direccion y gestión publica en el Municipio de Tenjo Cundinamarca | R13: 12 | S13: Actualizar mantener y fortalecer en un 100% la infraestructura de datos espaciales en el cuatrienio | T13: 0.4 | U13: Porcentaje | V13: I | W13: Funcionamiento garantizado | X13: Sec. de Planeación y Desarrollo Territorial | Z13: =SUM(AF13:AI13)/4 -> 1 | AA13: =AS13/Z13 -> 0.45 | AB13: =BI13/Z13 -> 0.9 | AE13: =SUMPRODUCT(AA13:AD13, {0.15,0.35,0.35,0.15}) -> 0.3825 | AF13: 1 | AG13: 1 | AH13: 1 | AI13: 1 | AN13: 0.5 | AO13: 0.5 | AP13: 0.5 | AQ13: 0.4 | AR13: =(AJ13+AL13+AN13+AP13)/2 -> 0.5 | AS13: =(AK13+AM13+AO13+AQ13)/2 -> 0.45 | AT13: =AS13/AR13 -> 0.9 | AU13: =MIN((AR13 /AR13) * 100, 100) & "%" -> 100% | AV13: =IF(AR13=0, 0, AS13/AR13) -> 0.9 | AW13: P | AX13: Meta 12.docx | AY13: 0.15 | AZ13: 0.15 | BA13: 0.3 | BB13: 0.3 | BC13: 0.45 | BD13: 0.45 | BE13: 0.1 | BG13: =(AY13+BA13+BC13+BE13) -> 1 | BH13: =(AZ13+BB13+BD13+BF13) -> 0.9 | BI13: =BH13/BG13 -> 0.9 | BJ13: =MIN((BG13 /BG13) * 100, 100) & "%" -> 100% | BK13: =IF(BG13=0, 0, BH13/BG13) -> 0.9 | BL13: P | BM13: Meta 12.docx | BN13: 442681049 | BO13: 44000000 | BP13: 11400000 | BQ13: 11400000 | BR13: =+BN13+BP13 -> 454081049 | BS13: =+BO13+BQ13 -> 55400000 | BT13: =IFERROR(BS13/BR13, "") -> 0.12200465 | BU13: 92681049 | BV13: 72681049 | BW13: 58000000 | BX13: 39266666 | BY13: =IFERROR(BW13/BV13, "") -> 0.79800719 | BZ13: 375000000 | CA13: 382500000 | CB13: 390150000 | CC13: 401854500 | CD13: 1549504500
A14: Eje 1. Ambiente, Conectividad y Ordenamiento y servicios públicos | B14: 0.235 | D14: 45 | E14: 4599 | F14: 3 | G14: Programa Avanzado de Gestión Territorial Inteligente (PRAGETI) (Fortalecimiento a la gestión y dirección de la gestió pública territorial) | H14: 1000 | I14: 3.1 | J14: Sistemas de Información y datos para la toma de decisiones | K14: 3.1.1 | L14: Implementar al 100% el sistema de Información y datos de gestión del desarrollo territorial y toma de decisiones, mediante la implementación efectiva de tecnologías avanzadas en análisis de datos y la optimización del funcionamiento de los consejos y comités de planificación y estratificación | M14: Porcentaje de sistema de Información y datos implementado | N14: 0.71 | O14: 4599025 | P14: 2024257990003 | Q14: Fortalecimiento a la direccion y gestión publica en el Municipio de Tenjo Cundinamarca | R14: 13 | S14: Garantizar el funcionamiento del servicio público de catastro multipropósito, logrando la hablilitación como Gestor Catastral al 100% | T14: 1 | U14: Porcentaje | V14: M | W14: Funcionamiento garantizado | X14: Sec. de Planeación y Desarrollo Territorial | Z14: =SUM(AF14:AI14) -> 1 | AA14: =AS14/Z14 -> 0.3 | AB14: =BI14/Z14 -> 0.6 | AE14: =SUMPRODUCT(AA14:AD14, {0.15,0.35,0.35,0.15}) -> 0.255 | AF14: 0.3 | AG14: 0.1 | AH14: 0.4 | AI14: 0.2 | AN14: 0.1 | AO14: 0.1 | AP14: 0.2 | AQ14: 0.2 | AR14: =(AJ14+AL14+AN14+AP14) -> 0.3 | AS14: =(AK14+AM14+AO14+AQ14) -> 0.3 | AT14: =AS14/AR14 -> 1 | AU14: =MIN((AR14 /AR14) * 100, 100) & "%" -> 100% | AV14: =IF(AR14=0, 0, AS14/AR14) -> 1 | AW14: P | AX14: Meta 13.docx | AY14: 0.03 | AZ14: 0.03 | BA14: 0.03 | BB14: 0 | BC14: 0.03 | BD14: 0.03 | BE14: 0.01 | BG14: =(AY14+BA14+BC14+BE14) -> 0.1 | BH14: =(AZ14+BB14+BD14+BF14) -> 0.06 | BI14: =BH14/BG14 -> 0.6 | BJ14: =MIN((BG14 /BG14) * 100, 100) & "%" -> 100% | BK14: =IF(BG14=0, 0, BH14/BG14) -> 0.6 | BL14: P | BM14: Meta 13.docx | BN14: 510000000 | BO14: 45000000 | BP14: 336500000 | BQ14: 336500000 | BR14: =+BN14+BP14 -> 846500000 | BS14: =+BO14+BQ14 -> 381500000 | BT14: =IFERROR(BS14/BR14, "") -> 0.45067927 | BU14: 510000000 | BV14: 120000000 | BW14: 31250000 | BX14: 11850000 | BY14: =IFERROR(BW14/BV14, "") -> 0.26041667 | BZ14: 500000000 | CA14: 510000000 | CB14: 520200000 | CC14: 535806000 | CD14: 2066006000
A15: Eje 1. Ambiente, Conectividad y Ordenamiento y servicios públicos | B15: 0.235 | D15: 45 | E15: 4599 | F15: 3 | G15: Programa Avanzado de Gestión Territorial Inteligente (PRAGETI) (Fortalecimiento a la gestión y dirección de la gestió pública territorial) | H15: 1000 | I15: 3.1 | J15: Sistemas de Información y datos para la toma de decisiones | K15: 3.1.1 | L15: Implementar al 100% el sistema de Información y datos de gestión del desarrollo territorial y toma de decisiones, mediante la implementación efectiva de tecnologías avanzadas en análisis de datos y la optimización del funcionamiento de los consejos y comités de planificación y estratificación | M15: Porcentaje de sistema de Información y datos implementado | N15: 0.71 | O15: 4599031 | P15: 2024257990003 | Q15: Fortalecimiento a la direccion y gestión publica en el Municipio de Tenjo Cundinamarca | R15: 14 | S15: Formular al 100% los proyectos de inversión para el cumplimiento de metas del plan de desarrollo municipal | T15: SD | U15: Porcentaje | V15: I | W15: Porcentaje de proyectos de inversión formulados y actualizados | X15: Sec. de Planeación y Desarrollo Territorial | Z15: =SUM(AF15:AI15)/4 -> 1 | AA15: =AS15/Z15 -> 0.475 | AB15: =BI15/Z15 -> 0.85 | AE15: =SUMPRODUCT(AA15:AD15, {0.15,0.35,0.35,0.15}) -> 0.36875 | AF15: 1 | AG15: 1 | AH15: 1 | AI15: 1 | AN15: 0.75 | AO15: 0.75 | AP15: 0.25 | AQ15: 0.2 | AR15: =(AJ15+AL15+AN15+AP15)/2 -> 0.5 | AS15: =(AK15+AM15+AO15+AQ15)/2 -> 0.475 | AT15: =AS15/AR15 -> 0.95 | AU15: =MIN((AR15 /AR15) * 100, 100) & "%" -> 100% | AV15: =IF(AR15=0, 0, AS15/AR15) -> 0.95 | AW15: P | AX15: Meta 14.docx | AY15: 0.25 | AZ15: 0.25 | BA15: 0.25 | BB15: 0.25 | BC15: 0.35 | BD15: 0.35 | BE15: 0.15 | BG15: =(AY15+BA15+BC15+BE15) -> 1 | BH15: =(AZ15+BB15+BD15+BF15) -> 0.85 | BI15: =BH15/BG15 -> 0.85 | BJ15: =MIN((BG15 /BG15) * 100, 100) & "%" -> 100% | BK15: =IF(BG15=0, 0, BH15/BG15) -> 0.85 | BL15: P | BM15: Meta 14.docx | BN15: 194000000 | BO15: 99753334 | BP15: 45533333 | BQ15: 45533333 | BR15: =+BN15+BP15 -> 239533333 | BS15: =+BO15+BQ15 -> 145286667 | BT15: =IFERROR(BS15/BR15, "") -> 0.6065405 | BU15: 170000000 | BV15: 103753334 | BW15: 99753334 | BX15: 76023333 | BY15: =IFERROR(BW15/BV15, "") -> 0.96144702 | BZ15: 160000000 | CA15: 163200000 | CB15: 166464000 | CC15: 171457920 | CD15: 661121920
A16: Eje 1. Ambiente, Conectividad y Ordenamiento y servicios públicos | B16: 0.235 | D16: 45 | E16: 4599 | F16: 3 | G16: Programa Avanzado de Gestión Territorial Inteligente (PRAGETI) (Fortalecimiento a la gestión y dirección de la gestió pública territorial) | H16: 1000 | I16: 3.1 | J16: Sistemas de Información y datos para la toma de decisiones | K16: 3.1.1 | L16: Implementar al 100% el sistema de Información y datos de gestión del desarrollo territorial y toma de decisiones, mediante la implementación efectiva de tecnologías avanzadas en análisis de datos y la optimización del funcionamiento de los consejos y comités de planificación y estratificación | M16: Porcentaje de sistema de Información y datos implementado | N16: 0.71 | O16: 4599032 | P16: 2024257990003 | Q16: Fortalecimiento a la direccion y gestión publica en el Municipio de Tenjo Cundinamarca | R16: 15 | S16: Desarrollar 4 seguimientos anuales a la ejecución del Plan de Desarrollo Territorial gerenado un esquema de ajuste a y mejoras en la toma de decisiones | T16: 4 | U16: Número | V16: M | W16: Seguimientos anuales al plan de Desarrollo realizados | X16: Sec. de Planeación y Desarrollo Territorial | Z16: =SUM(AF16:AI16) -> 16 | AA16: =AS16/Z16 -> 0.25 | AB16: =BI16/Z16 -> 0.0546875 | AE16: =SUMPRODUCT(AA16:AD16, {0.15,0.35,0.35,0.15}) -> 0.056640625 | AF16: 4 | AG16: 4 | AH16: 4 | AI16: 4 | AN16: 2 | AO16: 2 | AP16: 2 | AQ16: 2 | AR16: =(AJ16+AL16+AN16+AP16) -> 4 | AS16: =(AK16+AM16+AO16+AQ16) -> 4 | AT16: =AS16/AR16 -> 1 | AU16: =MIN((AR16 /AR16) * 100, 100) & "%" -> 100% | AV16: =IF(AR16=0, 0, AS16/AR16) -> 1 | AW16: P | AX16: Meta 15.docx | AY16: 1 | AZ16: 1 | BA16: 1 | BB16: 1 | BC16: 1.5 | BD16: 1.5 | BE16: 0.5 | BG16: =(AY16+BA16+BC16+BE16) -> 4 | BH16: =(AZ16+BB16+BD16+BF16) -> 3.5 | BI16: =BH16/BG16 -> 0.875 | BJ16: =MIN((BG16 /BG16) * 100, 100) & "%" -> 100% | BK16: =IF(BG16=0, 0, BH16/BG16) -> 0.875 | BL16: P | BM16: Meta 15.docx | BN16: 125000000 | BO16: 15000000 | BP16: 2000000 | BQ16: 2000000 | BR16: =+BN16+BP16 -> 127000000 | BS16: =+BO16+BQ16 -> 17000000 | BT16: =IFERROR(BS16/BR16, "") -> 0.13385827 | BU16: 125000000 | BV16: 63400000 | BW16: 63400000 | BX16: 21240000 | BY16: =IFERROR(BW16/BV16, "") -> 1 | BZ16: 110000000 | CA16: 112200000 | CB16: 114444000 | CC16: 117877320 | CD16: 454521320
A17: Eje 1. Ambiente, Conectividad y Ordenamiento y servicios públicos | B17: 0.235 | D17: 45 | E17: 4599 | F17: 3 | G17: Programa Avanzado de Gestión Territorial Inteligente (PRAGETI) (Fortalecimiento a la gestión y dirección de la gestió pública territorial) | H17: 1000 | I17: 3.1 | J17: Sistemas de Información y datos para la toma de decisiones | K17: 3.1.1 | L17: Implementar al 100% el sistema de Información y datos de gestión del desarrollo territorial y toma de decisiones, mediante la implementación efectiva de tecnologías avanzadas en análisis de datos y la optimización del funcionamiento de los consejos y comités de planificación y estratificación | M17: Porcentaje de sistema de Información y datos implementado | N17: 0.71 | O17: 4599023 | P17: 2024257990003 | Q17: Fortalecimiento a la direccion y gestión publica en el Municipio de Tenjo Cundinamarca | R17: 16 | S17: Implementar un modelo de gobierno de datos con el manejo de herramientas de analítica de datos para la toma de decisiones. | T17: 0 | U17: Número | V17: I | W17: Modelo de gobierno de datos implementado | X17: Sec. de Planeación y Desarrollo Territorial | Y17: SI | Z17: =SUM(AF17:AI17) -> 1 | AA17: =AS17/Z17 -> 1 | AB17: =BI17/Z17 -> 0.83333333 | AE17: =SUMPRODUCT(AA17:AD17, {0.15,0.35,0.35,0.15}) -> 0.44166667 | AF17: 0.2 | AG17: 0.3 | AH17: 0.3 | AI17: 0.2 | AN17: 0.4 | AO17: 0.4 | AP17: 0.6 | AQ17: 0.6 | AR17: =(AJ17+AL17+AN17+AP17) -> 1 | AS17: =(AK17+AM17+AO17+AQ17) -> 1 | AT17: =AS17/AR17 -> 1 | AU17: =MIN((AR17 /AR17) * 100, 100) & "%" -> 100% | AV17: =IF(AR17=0, 0, AS17/AR17) -> 1 | AW17: P | AX17: Meta 16.docx | AY17: 0.5 | AZ17: 0.5 | BA17: 0.5 | BB17: 0.5 | BC17: 1.5 | BD17: 1.5 | BE17: 0.5 | BG17: =(AY17+BA17+BC17+BE17) -> 3 | BH17: =(AZ17+BB17+BD17+BF17) -> 2.5 | BI17: =BH17/BG17 -> 0.83333333 | BJ17: =MIN((BG17 /BG17) * 100, 100) & "%" -> 100% | BK17: =IF(BG17=0, 0, BH17/BG17) -> 0.83333333 | BL17: P | BM17: Meta 16.docx | BN17: 71400000 | BO17: 71400000 | BP17: 88000000 | BQ17: 88000000 | BR17: =+BN17+BP17 -> 159400000 | BS17: =+BO17+BQ17 -> 159400000 | BT17: =IFERROR(BS17/BR17, "") -> 1 | BU17: 71400000 | BV17: 71400000 | BW17: 71400000 | BX17: 54442500 | BY17: =IFERROR(BW17/BV17, "") -> 1 | BZ17: 70000000 | CA17: 71400000 | CB17: 72828000 | CC17: 75012840 | CD17: 289240840
A18: Eje 1. Ambiente, Conectividad y Ordenamiento y servicios públicos | B18: 0.235 | D18: 45 | E18: 4599 | F18: 3 | G18: Programa Avanzado de Gestión Territorial Inteligente (PRAGETI) (Fortalecimiento a la gestión y dirección de la gestió pública territorial) | H18: 1000 | I18: 3.1 | J18: Sistemas de Información y datos para la toma de decisiones | K18: 3.1.1 | L18: Implementar al 100% el sistema de Información y datos de gestión del desarrollo territorial y toma de decisiones, mediante la implementación efectiva de tecnologías avanzadas en análisis de datos y la optimización del funcionamiento de los consejos y comités de planificación y estratificación | M18: Porcentaje de sistema de Información y datos implementado | N18: 0.71 | O18: 4599033 | P18: 2024257990003 | Q18: Fortalecimiento a la direccion y gestión publica en el Municipio de Tenjo Cundinamarca | R18: 17 | S18: Garantizar el sistema de información y el proceso de encuestas del sisben al 100% | T18: 1 | U18: Número | V18: M | W18: Funcionamiento garantizado | X18: Sec. de Planeación y Desarrollo Territorial | Z18: =SUM(AF18:AI18)/4 -> 1 | AA18: =AS18/Z18 -> 0.5 | AB18: =BI18/Z18 -> 0.85 | AE18: =SUMPRODUCT(AA18:AD18, {0.15,0.35,0.35,0.15}) -> 0.3725 | AF18: 1 | AG18: 1 | AH18: 1 | AI18: 1 | AN18: 0.75 | AO18: 0.75 | AP18: 0.25 | AQ18: 0.25 | AR18: =(AJ18+AL18+AN18+AP18)/2 -> 0.5 | AS18: =(AK18+AM18+AO18+AQ18)/2 -> 0.5 | AT18: =AS18/AR18 -> 1 | AU18: =MIN((AR18 /AR18) * 100, 100) & "%" -> 100% | AV18: =IF(AR18=0, 0, AS18/AR18) -> 1 | AW18: P | AX18: Meta 17.docx | AY18: 0.2 | AZ18: 0.2 | BA18: 0.25 | BB18: 0.25 | BC18: 0.4 | BD18: 0.4 | BE18: 0.15 | BG18: =(AY18+BA18+BC18+BE18) -> 1 | BH18: =(AZ18+BB18+BD18+BF18) -> 0.85 | BI18: =BH18/BG18 -> 0.85 | BJ18: =MIN((BG18 /BG18) * 100, 100) & "%" -> 100% | BK18: =IF(BG18=0, 0, BH18/BG18) -> 0.85 | BL18: P | BM18: Meta 17.docx | BN18: 110000000 | BO18: 93500000 | BP18: 24855200 | BQ18: 24855200 | BR18: =+BN18+BP18 -> 134855200 | BS18: =+BO18+BQ18 -> 118355200 | BT18: =IFERROR(BS18/BR18, "") -> 0.87764654 | BU18: 110000000 | BV18: 110000000 | BW18: 93500000 | BX18: 68113332 | BY18: =IFERROR(BW18/BV18, "") -> 0.85 | BZ18: 80000000 | CA18: 81600000 | CB18: 83232000 | CC18: 85728960 | CD18: 330560960
A19: Eje 1. Ambiente, Conectividad y Ordenamiento y servicios públicos | B19: 0.235 | D19: 45 | E19: 4599 | F19: 3 | G19: Programa Avanzado de Gestión Territorial Inteligente (PRAGETI) (Fortalecimiento a la gestión y dirección de la gestió pública territorial) | H19: 1000 | I19: 3.1 | J19: Sistemas de Información y datos para la toma de decisiones | K19: 3.1.1 | L19: Implementar al 100% el sistema de Información y datos de gestión del desarrollo territorial y toma de decisiones, mediante la implementación efectiva de tecnologías avanzadas en análisis de datos y la optimización del funcionamiento de los consejos y comités de planificación y estratificación | M19: Porcentaje de sistema de Información y datos implementado | N19: 0.71 | O19: 4599033 | P19: 2024257990003 | Q19: Fortalecimiento a la direccion y gestión publica en el Municipio de Tenjo Cundinamarca | R19: 18 | S19: Garantizar el funcionamiento del Consejo Territorial de Planeación | T19: 1 | U19: Número | V19: M | W19: Funcionamiento garantizado | X19: Sec. de Planeación y Desarrollo Territorial | Z19: =SUM(AF19:AI19)/4 -> 1 | AA19: =AS19/Z19 -> 1 | AB19: =BI19/Z19 -> 0.7 | AE19: =SUMPRODUCT(AA19:AD19, {0.15,0.35,0.35,0.15}) -> 0.395 | AF19: 1 | AG19: 1 | AH19: 1 | AI19: 1 | AN19: 0.5 | AO19: 0.5 | AP19: 0.5 | AQ19: 0.5 | AR19: =(AJ19+AL19+AN19+AP19) -> 1 | AS19: =(AK19+AM19+AO19+AQ19) -> 1 | AT19: =AS19/AR19 -> 1 | AU19: =MIN((AR19 /AR19) * 100, 100) & "%" -> 100% | AV19: =IF(AR19=0, 0, AS19/AR19) -> 1 | AW19: P | AX19: Meta 18.docx | AY19: 0.1 | AZ19: 0.1 | BA19: 0.1 | BB19: 0.1 | BC19: 0.5 | BD19: 0.5 | BE19: 0.3 | BG19: =(AY19+BA19+BC19+BE19) -> 1 | BH19: =(AZ19+BB19+BD19+BF19) -> 0.7 | BI19: =BH19/BG19 -> 0.7 | BJ19: =MIN((BG19 /BG19) * 100, 100) & "%" -> 100% | BK19: =IF(BG19=0, 0, BH19/BG19) -> 0.7 | BL19: P | BM19: Meta 18.docx | BN19: 15000000 | BO19: 0 | BP19: 0 | BQ19: 0 | BR19: =+BN19+BP19 -> 15000000 | BS19: =+BO19+BQ19 -> 0 | BT19: =IFERROR(BS19/BR19, "") -> 0 | BU19: 15000000 | BV19: 15000000 | BW19: 14930914 | BX19: 0 | BY19: =IFERROR(BW19/BV19, "") -> 0.99539427 | BZ19: 20000000 | CA19: 20400000 | CB19: 20808000 | CC19: 21432240 | CD19: 82640240
A20: Eje 1. Ambiente, Conectividad y Ordenamiento y servicios públicos | B20: 0.235 | D20: 45 | E20: 4599 | F20: 3 | G20: Programa Avanzado de Gestión Territorial Inteligente (PRAGETI) (Fortalecimiento a la gestión y dirección de la gestió pública territorial) | H20: 1000 | I20: 3.1 | J20: Sistemas de Información y datos para la toma de decisiones | K20: 3.1.1 | L20: Implementar al 100% el sistema de Información y datos de gestión del desarrollo territorial y toma de decisiones, mediante la implementación efectiva de tecnologías avanzadas en análisis de datos y la optimización del funcionamiento de los consejos y comités de planificación y estratificación | M20: Porcentaje de sistema de Información y datos implementado | N20: 0.71 | O20: 4599005 | P20: 2024257990003 | Q20: Fortalecimiento a la direccion y gestión publica en el Municipio de Tenjo Cundinamarca | R20: 19 | S20: Garantizar el funcionamiento de comité de estratificación | T20: 0.5 | U20: Porcentaje | V20: I | W20: Actalización aplicada | X20: Sec. de Planeación y Desarrollo Territorial | Z20: =SUM(AF20:AI20)/4 -> 1 | AA20: =AS20/Z20 -> 0.98 | AB20: =BI20/Z20 -> 0.5 | AE20: =SUMPRODUCT(AA20:AD20, {0.15,0.35,0.35,0.15}) -> 0.322 | AF20: 1 | AG20: 1 | AH20: 1 | AI20: 1 | AN20: 0.4 | AO20: 0.4 | AP20: 0.6 | AQ20: 0.58 | AR20: =(AJ20+AL20+AN20+AP20) -> 1 | AS20: =(AK20+AM20+AO20+AQ20) -> 0.98 | AT20: =AS20/AR20 -> 0.98 | AU20: =MIN((AR20 /AR20) * 100, 100) & "%" -> 100% | AV20: =IF(AR20=0, 0, AS20/AR20) -> 0.98 | AW20: P | AX20: Meta 19.docx | AY20: 0 | AZ20: 0 | BA20: 0 | BB20: 0 | BC20: 0.5 | BD20: 0.5 | BE20: 0.5 | BG20: =(AY20+BA20+BC20+BE20) -> 1 | BH20: =(AZ20+BB20+BD20+BF20) -> 0.5 | BI20: =BH20/BG20 -> 0.5 | BJ20: =MIN((BG20 /BG20) * 100, 100) & "%" -> 100% | BK20: =IF(BG20=0, 0, BH20/BG20) -> 0.5 | BL20: P | BM20: Meta 19.docx | BN20: 5100000 | BO20: 0 | BP20: 195173 | BQ20: 195173 | BR20: =+BN20+BP20 -> 5295173 | BS20: =+BO20+BQ20 -> 195173 | BT20: =IFERROR(BS20/BR20, "") -> 0.036858664 | BU20: 5100000 | BV20: 5100000 | BW20: 208835 | BX20: 208835 | BY20: =IFERROR(BW20/BV20, "") -> 0.040948039 | BZ20: 5000000 | CA20: 5100000 | CB20: 5202000 | CC20: 5358060 | CD20: 20660060
A21: Eje 1. Ambiente, Conectividad y Ordenamiento y servicios públicos | B21: 0.235 | D21: 40 | E21: 4002 | F21: 4 | G21: Ordenamiento Territorial y Desarrollo Urbano Inteligente y Sostenible-OTEDUS (Ordenamiento territorial y desarrollo urbano) | H21: 1400 | I21: 4.1 | J21: Ordenamiento Territorial Inteligente | K21: 4.1.1 | L21: Garantizar al 100% las acciones de revisión, ajustes y actualización de PBOT | M21: Porcentaje de acciones de garantizadas | N21: 0.2 | O21: 4002018 | P21: 2024257990004 | Q21: Implementación del Desarrollo Urbano y Ordenamiento Territorial Inteligente en el Municipio de Tenjo Cundinamarca | R21: 20 | S21: Desarrollar un programa de actualización cartográfica | T21: 0 | U21: Número | V21: I | W21: Programa desarrollado | X21: Sec. de Planeación y Desarrollo Territorial | Z21: =SUM(AF21:AI21) -> 1 | AA21: =AS21/Z21 -> 0.88 | AB21: =BI21/Z21 -> 0 | AE21: =SUMPRODUCT(AA21:AD21, {0.15,0.35,0.35,0.15}) -> 0.132 | AF21: 1 | AG21: 0 | AH21: 0 | AI21: 0 | AN21: 0.7 | AO21: 0.7 | AP21: 0.3 | AQ21: 0.18 | AR21: =(AJ21+AL21+AN21+AP21) -> 1 | AS21: =(AK21+AM21+AO21+AQ21) -> 0.88 | AT21: =AS21/AR21 -> 0.88 | AU21: =MIN((AR21 /AR21) * 100, 100) & "%" -> 100% | AV21: =IF(AR21=0, 0, AS21/AR21) -> 0.88 | AW21: P | AX21: Meta 20.docx | AY21: 0 | BA21: 0 | BB21: 0 | BC21: 0 | BE21: 0 | BG21: =(AY21+BA21+BC21+BE21) -> 0 | BH21: =(AZ21+BB21+BD21+BF21) -> 0 | BI21: =IF(BF21> 1, IF(BF21 = BG21, "100%", BF21 & "%"), IF(BF21 <= 0.01, "0%", BF21 * 100 & "%")) -> 0% | BJ21: =IF(BF21=0, 0, BG21/BF21) -> 0 | BK21: =IF(BG21=0, 0, BH21/BG21) -> 0 | BL21: NP | BM21: Meta 20.docx | BN21: 0 | BO21: 0 | BP21: 646022333 | BQ21: 646022333 | BR21: =+BN21+BP21 -> 646022333 | BS21: =+BO21+BQ21 -> 646022333 | BT21: =IFERROR(BS21/BR21, "") -> 1 | BU21: 0 | BV21: 0 | BW21: 0 | BX21: 0 | BY21: =IFERROR(BW21/BV21, "") | BZ21: 650000000 | CA21: 0 | CB21: 0 | CC21: 0 | CD21: 650000000
A22: Eje 1. Ambiente, Conectividad y Ordenamiento y servicios públicos | B22: 0.235 | D22: 40 | E22: 4002 | F22: 4 | G22: Ordenamiento Territorial y Desarrollo Urbano Inteligente y Sostenible-OTEDUS (Ordenamiento territorial y desarrollo urbano) | H22: 1400 | I22: 4.1 | J22: Ordenamiento Territorial Inteligente | K22: 4.1.1 | L22: Garantizar al 100% las acciones de revisión, ajustes y actualización de PBOT | M22: Porcentaje de acciones de garantizadas | N22: 0.2 | O22: 4002001 | P22: 2024257990004 | Q22: Implementación del Desarrollo Urbano y Ordenamiento Territorial Inteligente en el Municipio de Tenjo Cundinamarca | R22: 21 | S22: Realizar un proceso de revisión y ajustes al PBOT en el cuatrienio | T22: 0 | U22: Número | V22: I | W22: Proceso de revisión realizado | X22: Sec. de Planeación y Desarrollo Territorial | Z22: =SUM(AF22:AI22) -> 1 | AA22: =AS22/Z22 -> 0.2 | AB22: =BI22/Z22 -> 0.875 | AE22: =SUMPRODUCT(AA22:AD22, {0.15,0.35,0.35,0.15}) -> 0.33625 | AF22: 0.2 | AG22: 0.4 | AH22: 0.3 | AI22: 0.1 | AN22: 0.1 | AO22: 0.1 | AP22: 0.1 | AQ22: 0.1 | AR22: =(AJ22+AL22+AN22+AP22) -> 0.2 | AS22: =(AK22+AM22+AO22+AQ22) -> 0.2 | AT22: =AS22/AR22 -> 1 | AU22: =MIN((AR22 /AR22) * 100, 100) & "%" -> 100% | AV22: =IF(AR22=0, 0, AS22/AR22) -> 1 | AW22: P | AX22: Meta 21.docx | AY22: 0.1 | AZ22: 0.1 | BA22: 0.1 | BB22: 0.1 | BC22: 0.15 | BD22: 0.15 | BE22: 0.05 | BG22: =(AY22+BA22+BC22+BE22) -> 0.4 | BH22: =(AZ22+BB22+BD22+BF22) -> 0.35 | BI22: =BH22/BG22 -> 0.875 | BJ22: =MIN((BG22 /BG22) * 100, 100) & "%" -> 100% | BK22: =IF(BG22=0, 0, BH22/BG22) -> 0.875 | BL22: P | BM22: Meta 21.docx | BN22: 300000000 | BO22: 184400000 | BP22: 54746667 | BQ22: 54746667 | BR22: =+BN22+BP22 -> 354746667 | BS22: =+BO22+BQ22 -> 239146667 | BT22: =IFERROR(BS22/BR22, "") -> 0.67413365 | BU22: 300000000 | BV22: 224400000 | BW22: 211950000 | BX22: 155066666 | BY22: =IFERROR(BW22/BV22, "") -> 0.94451872 | BZ22: 180000000 | CA22: 183600000 | CB22: 187272000 | CC22: 192890160 | CD22: 743762160
A23: Eje 1. Ambiente, Conectividad y Ordenamiento y servicios públicos | B23: 0.235 | D23: 40 | E23: 4002 | F23: 4 | G23: Ordenamiento Territorial y Desarrollo Urbano Inteligente y Sostenible-OTEDUS (Ordenamiento territorial y desarrollo urbano) | H23: 1400 | I23: 4.1 | J23: Ordenamiento Territorial Inteligente | K23: 4.1.1 | L23: Garantizar al 100% las acciones de revisión, ajustes y actualización de PBOT | M23: Porcentaje de acciones de garantizadas | N23: 0.2 | O23: 4002016 | P23: 2024257990004 | Q23: Implementación del Desarrollo Urbano y Ordenamiento Territorial Inteligente en el Municipio de Tenjo Cundinamarca | R23: 22 | S23: Mantener actualizado al 100% el expediente municipal del PBOT | T23: 0.6 | U23: Porcentaje | V23: M | W23: Expediente municipal fortalecido | X23: Sec. de Planeación y Desarrollo Territorial | Z23: =SUM(AF23:AI23)/4 -> 1 | AA23: =AS23/Z23 -> 0.5 | AB23: =BI23/Z23 -> 0.85 | AE23: =SUMPRODUCT(AA23:AD23, {0.15,0.35,0.35,0.15}) -> 0.3725 | AF23: 1 | AG23: 1 | AH23: 1 | AI23: 1 | AN23: 0.2 | AO23: 0.2 | AP23: 0.8 | AQ23: 0.8 | AR23: =(AJ23+AL23+AN23+AP23)/2 -> 0.5 | AS23: =(AK23+AM23+AO23+AQ23)/2 -> 0.5 | AT23: =AS23/AR23 -> 1 | AU23: =MIN((AR23 /AR23) * 100, 100) & "%" -> 100% | AV23: =IF(AR23=0, 0, AS23/AR23) -> 1 | AW23: P | AX23: Meta 22.docx | AY23: 0.15 | AZ23: 0.15 | BA23: 0.3 | BB23: 0.3 | BC23: 0.4 | BD23: 0.4 | BE23: 0.15 | BG23: =(AY23+BA23+BC23+BE23) -> 1 | BH23: =(AZ23+BB23+BD23+BF23) -> 0.85 | BI23: =BH23/BG23 -> 0.85 | BJ23: =MIN((BG23 /BG23) * 100, 100) & "%" -> 100% | BK23: =IF(BG23=0, 0, BH23/BG23) -> 0.85 | BL23: P | BM23: Meta 22.docx | BN23: 72000000 | BO23: 35530000 | BP23: 0 | BQ23: 0 | BR23: =+BN23+BP23 -> 72000000 | BS23: =+BO23+BQ23 -> 35530000 | BT23: =IFERROR(BS23/BR23, "") -> 0.49347222 | BU23: 72000000 | BV23: 35530000 | BW23: 35530000 | BX23: 25630000 | BY23: =IFERROR(BW23/BV23, "") -> 1 | BZ23: 131000000 | CA23: 133620000 | CB23: 136292400 | CC23: 140381172 | CD23: 541293572
A24: Eje 1. Ambiente, Conectividad y Ordenamiento y servicios públicos | B24: 0.235 | D24: 40 | E24: 4002 | F24: 4 | G24: Ordenamiento Territorial y Desarrollo Urbano Inteligente y Sostenible-OTEDUS (Ordenamiento territorial y desarrollo urbano) | H24: 1400 | I24: 4.1 | J24: Ordenamiento Territorial Inteligente | K24: 4.1.2 | L24: Garantizar al 100% las acciones de implementación del PEMP programadas para el cuatrienio | M24: Porcentaje de acciones de garantizadas | N24: 0 | O24: 4002015 | P24: 2024257990004 | Q24: Implementación del Desarrollo Urbano y Ordenamiento Territorial Inteligente en el Municipio de Tenjo Cundinamarca | R24: 23 | S24: Ejecutar el 30% del Plan Especial de Manejo y Protección PEMP con base en lineamientos de MinCultura | T24: SD | U24: Porcentaje | V24: I | W24: PEMP actualizado | X24: Sec. de Planeación y Desarrollo Territorial | Z24: =SUM(AF24:AI24) -> 0.3 | AA24: =AS24/Z24 -> 0.33333333 | AB24: =BI24/Z24 -> 2.8333333 | AE24: =SUMPRODUCT(AA24:AD24, {0.15,0.35,0.35,0.15}) -> 1.0416667 | AF24: 0.1 | AG24: 0.1 | AH24: 0.05 | AI24: 0.05 | AN24: 0.05 | AO24: 0.05 | AP24: 0.05 | AQ24: 0.05 | AR24: =(AJ24+AL24+AN24+AP24) -> 0.1 | AS24: =(AK24+AM24+AO24+AQ24) -> 0.1 | AT24: =AS24/AR24 -> 1 | AU24: =MIN((AR24 /AR24) * 100, 100) & "%" -> 100% | AV24: =IF(AR24=0, 0, AS24/AR24) -> 1 | AW24: P | AX24: Meta 23.docx | AY24: 0.025 | AZ24: 0.025 | BA24: 0.025 | BB24: 0.025 | BC24: 0.035 | BD24: 0.035 | BE24: 0.015 | BG24: =(AY24+BA24+BC24+BE24) -> 0.1 | BH24: =(AZ24+BB24+BD24+BF24) -> 0.085 | BI24: =BH24/BG24 -> 0.85 | BJ24: =MIN((BG24 /BG24) * 100, 100) & "%" -> 100% | BK24: =IF(BG24=0, 0, BH24/BG24) -> 0.85 | BL24: P | BM24: Meta 23.docx | BN24: 55000000 | BO24: 47700000 | BP24: 16500000 | BQ24: 16500000 | BR24: =+BN24+BP24 -> 71500000 | BS24: =+BO24+BQ24 -> 64200000 | BT24: =IFERROR(BS24/BR24, "") -> 0.8979021 | BU24: 55000000 | BV24: 55000000 | BW24: 47700000 | BX24: 34350000 | BY24: =IFERROR(BW24/BV24, "") -> 0.86727273 | BZ24: 40000000 | CA24: 40800000 | CB24: 41616000 | CC24: 42864480 | CD24: 165280480
A25: Eje 1. Ambiente, Conectividad y Ordenamiento y servicios públicos | B25: 0.235 | D25: 40 | E25: 4002 | F25: 4 | G25: Ordenamiento Territorial y Desarrollo Urbano Inteligente y Sostenible-OTEDUS (Ordenamiento territorial y desarrollo urbano) | H25: 1400 | I25: 4.1 | J25: Ordenamiento Territorial Inteligente | K25: 4.1.2 | L25: Garantizar al 100% las acciones de implementación del PEMP programadas para el cuatrienio | M25: Porcentaje de acciones de garantizadas | N25: 0 | O25: 4002023 | P25: 2024257990004 | Q25: Implementación del Desarrollo Urbano y Ordenamiento Territorial Inteligente en el Municipio de Tenjo Cundinamarca | R25: 24 | S25: Modernizar la infraestructura física del Parque Principal optimizando la actividad turística y el valor patrimonial del municipio de Tenjo en concordancia con el PEMP | T25: 0 | U25: Número | V25: I | W25: Número de parques modernizados | X25: Sec. Infraestructura y Obra Pública | Z25: =SUM(AF25:AI25) -> 1 | AA25: =AS25/Z25 -> 0 | AB25: =BI25/Z25 -> 0.85 | AE25: =SUMPRODUCT(AA25:AD25, {0.15,0.35,0.35,0.15}) -> 0.2975 | AF25: 0 | AG25: 0.2 | AH25: 0.7 | AI25: 0.1 | AN25: 0 | AO25: 0 | AP25: 0 | AQ25: 0 | AR25: 0 | AS25: 0 | AT25: 0 | AU25: =IF(AR25> 1, IF(AR25 = AS25, "100%", AR25 & "%"), IF(AR25 <= 0.01, "0%", AR25 * 100 & "%")) -> 0% | AV25: =IF(AR25=0, 0, AS25/AR25) -> 0 | AW25: NP | AY25: 0.02 | AZ25: 0.02 | BA25: 0.03 | BB25: 0.03 | BC25: 0.12 | BD25: 0.12 | BE25: 0.03 | BG25: =(AY25+BA25+BC25+BE25) -> 0.2 | BH25: =(AZ25+BB25+BD25+BF25) -> 0.17 | BI25: =BH25/BG25 -> 0.85 | BJ25: =MIN((BG25 /BG25) * 100, 100) & "%" -> 100% | BK25: =IF(BG25=0, 0, BH25/BG25) -> 0.85 | BL25: P | BM25: Meta 24.docx | BN25: 50000000 | BO25: 0 | BP25: 0 | BQ25: 0 | BR25: =+BN25+BP25 -> 50000000 | BS25: =+BO25+BQ25 -> 0 | BT25: =IFERROR(BS25/BR25, "") -> 0 | BU25: 50000000 | BV25: 50000000 | BW25: 50000000 | BX25: 0 | BY25: =IFERROR(BW25/BV25, "") -> 1 | BZ25: 0 | CA25: 0 | CB25: 0 | CC25: 200000000 | CD25: 200000000
A26: Eje 1. Ambiente, Conectividad y Ordenamiento y servicios públicos | B26: 0.235 | D26: 40 | E26: 4003 | F26: 5 | G26: Programa Integral de Innovación de Servicios Públicos de Acuedcto, Alcantarillado y Aseo (PISAAA) (Acceso de la población a los servicios de agua potable y saneamiento básico) | H26: 1400 | I26: 5.1 | J26: Es el tiempo de Agua Potable con Calidad | K26: 5.1.1 | L26: Incrementar al 99% la calidad y continuidad del servicio de acueducto | M26: Porcentaje de calidad y continuidad del servicios de acueducto incrementado | N26: % en el municipio 97,93 % en la cabecera municipal 99,58 % Centros poblados y rural disperso 96,73 Fuente: Dane.mapa.argis.com | O26: 4003017 | P26: 2024257990005 | Q26: Optimización del programa integral para el acceso de la población a los serivicios de agua potable y saneamiento básico en el municipio de Tenjo Cundinamarca | R26: 25 | S26: Optimizar 27 km de redes de acueducto | T26: 2 km | U26: Km | V26: M | W26: Km de redes de acueducto optimizadas | X26: Sec. Infraestructura y Obra Pública | Y26: SI | Z26: =SUM(AF26:AI26) -> 27 | AA26: =AS26/Z26 -> 0.22222222 | AB26: =BI26/Z26 -> 0.03 | AE26: =SUMPRODUCT(AA26:AD26, {0.15,0.35,0.35,0.15}) -> 0.043833333 | AF26: 6 | AG26: 10 | AH26: 6 | AI26: 5 | AN26: 0.001 | AO26: 0 | AP26: 6 | AQ26: 6 | AR26: =(AJ26+AL26+AN26+AP26) -> 6.001 | AS26: =(AK26+AM26+AO26+AQ26) -> 6 | AT26: =AS26/AR26 -> 0.99983336 | AU26: =MIN((AR26 /AR26) * 100, 100) & "%" -> 100% | AV26: =IF(AR26=0, 0, AS26/AR26) -> 0.99983336 | AW26: P | AX26: META 25.docx | AY26: 0.2 | AZ26: 0.2 | BA26: 0.1 | BB26: 0.2 | BC26: 7.7 | BD26: 7.7 | BE26: 2 | BG26: =(AY26+BA26+BC26+BE26) -> 10 | BH26: =(AZ26+BB26+BD26+BF26) -> 8.1 | BI26: =BH26/BG26 -> 0.81 | BJ26: =MIN((BG26 /BG26) * 100, 100) & "%" -> 100% | BK26: =IF(BG26=0, 0, BH26/BG26) -> 0.81 | BL26: P | BM26: Meta 25.docx | BN26: 400000000 | BO26: 86925000 | BP26: 1323000000 | BQ26: 1323000000 | BR26: =+BN26+BP26 -> 1723000000 | BS26: =+BO26+BQ26 -> 1409925000 | BT26: =IFERROR(BS26/BR26, "") -> 0.81829658 | BU26: 100000000 | BV26: 400000000 | BW26: 86925000 | BX26: 65487500 | BY26: =IFERROR(BW26/BV26, "") -> 0.2173125 | BZ26: 800000000 | CA26: 900000000 | CB26: 0 | CC26: 1166398880 | CD26: 2866398880
A27: Eje 1. Ambiente, Conectividad y Ordenamiento y servicios públicos | B27: 0.235 | D27: 40 | E27: 4003 | F27: 5 | G27: Programa Integral de Innovación de Servicios Públicos de Acuedcto, Alcantarillado y Aseo (PISAAA) (Acceso de la población a los servicios de agua potable y saneamiento básico) | H27: 1400 | I27: 5.1 | J27: Es el tiempo de Agua Potable con Calidad | K27: 5.1.1 | L27: Incrementar al 99% la calidad y continuidad del servicio de acueducto | M27: Porcentaje de calidad y continuidad del servicios de acueducto incrementado | N27: % en el municipio 97,93 % en la cabecera municipal 99,58 % Centros poblados y rural disperso 96,73 Fuente: Dane.mapa.argis.com | O27: 4003009 | P27: 2024257990005 | Q27: Optimización del programa integral para el acceso de la población a los serivicios de agua potable y saneamiento básico en el municipio de Tenjo Cundinamarca | R27: 26 | S27: Optimizar la macromedición y sectorización al 80% en el municipio de Tenjo en las redes de acueducto. | T27: 7,75% | U27: Porcentaje | V27: I | W27: Porcentaje de macro medición y sectorización optimizadas | X27: Sec. Infraestructura y Obra Pública | Y27: SI | Z27: =SUM(AF27:AI27) -> 0.8 | AA27: =AS27/Z27 -> 0.375 | AB27: =BI27/Z27 -> 0.625 | AE27: =SUMPRODUCT(AA27:AD27, {0.15,0.35,0.35,0.15}) -> 0.275 | AF27: 0.3 | AG27: 0.4 | AH27: 0.1 | AI27: 0 | AN27: 1e-05 | AO27: 0 | AP27: 0.3 | AQ27: 0.3 | AR27: =(AJ27+AL27+AN27+AP27) -> 0.30001 | AS27: =(AK27+AM27+AO27+AQ27) -> 0.3 | AT27: =AS27/AR27 -> 0.99996667 | AU27: =MIN((AR27 /AR27) * 100, 100) & "%" -> 100% | AV27: =IF(AR27=0, 0, AS27/AR27) -> 0.99996667 | AW27: P | AX27: META 26.docx | AY27: 0 | AZ27: 0 | BA27: 0 | BB27: 0 | BC27: 0.2 | BD27: 0.2 | BE27: 0.2 | BG27: =(AY27+BA27+BC27+BE27) -> 0.4 | BH27: =(AZ27+BB27+BD27+BF27) -> 0.2 | BI27: =BH27/BG27 -> 0.5 | BJ27: =MIN((BG27 /BG27) * 100, 100) & "%" -> 100% | BK27: =IF(BG27=0, 0, BH27/BG27) -> 0.5 | BL27: P | BM27: Meta 26.docx | BN27: 100000000 | BO27: 0 | BP27: 800000000 | BQ27: 800000000 | BR27: =+BN27+BP27 -> 900000000 | BS27: =+BO27+BQ27 -> 800000000 | BT27: =IFERROR(BS27/BR27, "") -> 0.88888889 | BU27: 100000000 | BV27: 100000000 | BW27: 0 | BX27: 0 | BY27: =IFERROR(BW27/BV27, "") -> 0 | BZ27: 125000000 | CA27: 100000000 | CB27: 120000000 | CC27: 125000000 | CD27: 470000000
